Traceback (most recent call last):
  File "/home/varun/anaconda3/envs/lightningenv/lib/python3.10/site-packages/jupyter_cache/executors/utils.py", line 58, in single_nb_execution
    executenb(
  File "/home/varun/anaconda3/envs/lightningenv/lib/python3.10/site-packages/nbclient/client.py", line 1204, in execute
    return NotebookClient(nb=nb, resources=resources, km=km, **kwargs).execute()
  File "/home/varun/anaconda3/envs/lightningenv/lib/python3.10/site-packages/nbclient/util.py", line 84, in wrapped
    return just_run(coro(*args, **kwargs))
  File "/home/varun/anaconda3/envs/lightningenv/lib/python3.10/site-packages/nbclient/util.py", line 62, in just_run
    return loop.run_until_complete(coro)
  File "/home/varun/anaconda3/envs/lightningenv/lib/python3.10/asyncio/base_events.py", line 649, in run_until_complete
    return future.result()
  File "/home/varun/anaconda3/envs/lightningenv/lib/python3.10/site-packages/nbclient/client.py", line 663, in async_execute
    await self.async_execute_cell(
  File "/home/varun/anaconda3/envs/lightningenv/lib/python3.10/site-packages/nbclient/client.py", line 965, in async_execute_cell
    await self._check_raise_for_error(cell, cell_index, exec_reply)
  File "/home/varun/anaconda3/envs/lightningenv/lib/python3.10/site-packages/nbclient/client.py", line 862, in _check_raise_for_error
    raise CellExecutionError.from_cell_and_msg(cell, exec_reply_content)
nbclient.exceptions.CellExecutionError: An error occurred while executing the following cell:
------------------
GT = sorted(glob('RealMask/*.tif'))
Prediction = sorted(glob('human_breast_carcinoma_s256/VollSeg/*.tif'))
Results = 'HumanBreastCells/Metrics/'
Path(Results).mkdir(exist_ok=True)
model_name = 'human_breast_carcinoma_s256'


------------------

[0;31m---------------------------------------------------------------------------[0m
[0;31mFileNotFoundError[0m                         Traceback (most recent call last)
Cell [0;32mIn[3], line 4[0m
[1;32m      2[0m Prediction [38;5;241m=[39m [38;5;28msorted[39m(glob([38;5;124m'[39m[38;5;124mhuman_breast_carcinoma_s256/VollSeg/*.tif[39m[38;5;124m'[39m))
[1;32m      3[0m Results [38;5;241m=[39m [38;5;124m'[39m[38;5;124mHumanBreastCells/Metrics/[39m[38;5;124m'[39m
[0;32m----> 4[0m [43mPath[49m[43m([49m[43mResults[49m[43m)[49m[38;5;241;43m.[39;49m[43mmkdir[49m[43m([49m[43mexist_ok[49m[38;5;241;43m=[39;49m[38;5;28;43;01mTrue[39;49;00m[43m)[49m
[1;32m      5[0m model_name [38;5;241m=[39m [38;5;124m'[39m[38;5;124mhuman_breast_carcinoma_s256[39m[38;5;124m'[39m

File [0;32m~/anaconda3/envs/lightningenv/lib/python3.10/pathlib.py:1175[0m, in [0;36mPath.mkdir[0;34m(self, mode, parents, exist_ok)[0m
[1;32m   1171[0m [38;5;250m[39m[38;5;124;03m"""[39;00m
[1;32m   1172[0m [38;5;124;03mCreate a new directory at this given path.[39;00m
[1;32m   1173[0m [38;5;124;03m"""[39;00m
[1;32m   1174[0m [38;5;28;01mtry[39;00m:
[0;32m-> 1175[0m     [38;5;28;43mself[39;49m[38;5;241;43m.[39;49m[43m_accessor[49m[38;5;241;43m.[39;49m[43mmkdir[49m[43m([49m[38;5;28;43mself[39;49m[43m,[49m[43m [49m[43mmode[49m[43m)[49m
[1;32m   1176[0m [38;5;28;01mexcept[39;00m [38;5;167;01mFileNotFoundError[39;00m:
[1;32m   1177[0m     [38;5;28;01mif[39;00m [38;5;129;01mnot[39;00m parents [38;5;129;01mor[39;00m [38;5;28mself[39m[38;5;241m.[39mparent [38;5;241m==[39m [38;5;28mself[39m:

[0;31mFileNotFoundError[0m: [Errno 2] No such file or directory: 'HumanBreastCells/Metrics'
FileNotFoundError: [Errno 2] No such file or directory: 'HumanBreastCells/Metrics'

